Workbook

Sheet Study Information
A1: Study Number | B1: 999-999 | D1: Expected Countries | E1: Initial Country? | F1: Country ER | G1: Participants Per Country | H1: Participants Per Country with SF Rate | I1: # of Sites | J1: Average Time to Activate Site | K1: Submission Date | L1: Estimated Approval | M1: Target Submission Date for FPS | N1: Site Activation Timeline | O1: 1 | P1: 2 | Q1: 3 | R1: 4 | S1: 5 | T1: 6 | U1: 7 | V1: 8 | W1: 9 | X1: 10 | Y1: 11 | Z1: 12 | AA1: 13 | AB1: 14 | AC1: 15 | AD1: 16 | AE1: 17 | AF1: 18 | AG1: 19 | AH1: 20
A2: Total Participants Needed | B2: 100 | D2: United States | E2: Yes | F2: 0.3 | G2: 44 | H2: =IF(G2="","",ROUND(G2-(G2*$B$6),0)) -> 37 | I2: 4 | J2: 30 | K2: 45809 | L2: =IF(D2="","",K2+_xlfn.XLOOKUP(D2,'Country StartUp'!A:A,'Country StartUp'!B:B)) -> 45869 | M2: =IF(D2="","",$B$3-_xlfn.XLOOKUP(D2,'Country StartUp'!A:A,'Country StartUp'!B:B)) -> 45963 | O2: =IF(OR($L2="",$I2<O$1),"",$L2+J2) -> 45899 | P2: =IF(OR($O2="",$I2<P$1),"",$J2+O2) -> 45929 | Q2: =IF(OR($O2="",$I2<Q$1),"",$J2+P2) -> 45959 | R2: =IF(OR($O2="",$I2<R$1),"",$J2+Q2) -> 45989 | S2: =IF(OR($O2="",$I2<S$1),"",$J2+R2) | T2: =IF(OR($O2="",$I2<T$1),"",$J2+S2) | U2: =IF(OR($O2="",$I2<U$1),"",$J2+T2) | V2: =IF(OR($O2="",$I2<V$1),"",$J2+U2) | W2: =IF(OR($O2="",$I2<W$1),"",$J2+V2) | ... AH2: =IF(OR($O2="",$I2<AH$1),"",$J2+AG2)
A3: Target FPS Date | B3: 46023 | D3: Germany | E3: Yes | F3: 0.1 | G3: 55 | H3: =IF(G3="","",ROUND(G3-(G3*$B$6),0)) -> 47 | I3: 8 | J3: 45 | K3: 45870 | L3: =IF(D3="","",K3+_xlfn.XLOOKUP(D3,'Country StartUp'!A:A,'Country StartUp'!B:B)) -> 45996.545 | M3: =IF(D3="","",$B$3-_xlfn.XLOOKUP(D3,'Country StartUp'!A:A,'Country StartUp'!B:B)) -> 45896.455 | O3: =IF(OR($L3="",$I3<O$1),"",$L3+J3) -> 46041.545 | P3: =IF(OR($O3="",$I3<P$1),"",$J3+O3) -> 46086.545 | Q3: =IF(OR($O3="",$I3<Q$1),"",$J3+P3) -> 46131.545 | R3: =IF(OR($O3="",$I3<R$1),"",$J3+Q3) -> 46176.545 | S3: =IF(OR($O3="",$I3<S$1),"",$J3+R3) -> 46221.545 | T3: =IF(OR($O3="",$I3<T$1),"",$J3+S3) -> 46266.545 | U3: =IF(OR($O3="",$I3<U$1),"",$J3+T3) -> 46311.545 | V3: =IF(OR($O3="",$I3<V$1),"",$J3+U3) -> 46356.545 | W3: =IF(OR($O3="",$I3<W$1),"",$J3+V3) | ... AH3: =IF(OR($O3="",$I3<AH$1),"",$J3+AG3)
A4: Target FPI/FPD Date | B4: =B3+B8 -> 46053 | D4: Canada | E4: Yes | F4: 0.15 | G4: 20 | H4: =IF(G4="","",ROUND(G4-(G4*$B$6),0)) -> 17 | I4: 2 | J4: 90 | K4: 45870 | L4: =IF(D4="","",K4+_xlfn.XLOOKUP(D4,'Country StartUp'!A:A,'Country StartUp'!B:B)) -> 45915.667 | M4: =IF(D4="","",$B$3-_xlfn.XLOOKUP(D4,'Country StartUp'!A:A,'Country StartUp'!B:B)) -> 45977.333 | O4: =IF(OR($L4="",$I4<O$1),"",$L4+J4) -> 46005.667 | P4: =IF(OR($O4="",$I4<P$1),"",$J4+O4) -> 46095.667 | Q4: =IF(OR($O4="",$I4<Q$1),"",$J4+P4) | R4: =IF(OR($O4="",$I4<R$1),"",$J4+Q4) | S4: =IF(OR($O4="",$I4<S$1),"",$J4+R4) | T4: =IF(OR($O4="",$I4<T$1),"",$J4+S4) | U4: =IF(OR($O4="",$I4<U$1),"",$J4+T4) | V4: =IF(OR($O4="",$I4<V$1),"",$J4+U4) | W4: =IF(OR($O4="",$I4<W$1),"",$J4+V4) | ... AH4: =IF(OR($O4="",$I4<AH$1),"",$J4+AG4)
A5: Target LPI Date | B5: 46388 | D5: Spain | E5: No | F5: 0.3 | G5: 85 | H5: =IF(G5="","",ROUND(G5-(G5*$B$6),0)) -> 72 | I5: 16 | J5: 60 | K5: 45931 | L5: =IF(D5="","",K5+_xlfn.XLOOKUP(D5,'Country StartUp'!A:A,'Country StartUp'!B:B)) -> 46049.466 | M5: =IF(D5="","",$B$3-_xlfn.XLOOKUP(D5,'Country StartUp'!A:A,'Country StartUp'!B:B)) -> 45904.534 | O5: =IF(OR($L5="",$I5<O$1),"",$L5+J5) -> 46109.466 | P5: =IF(OR($O5="",$I5<P$1),"",$J5+O5) -> 46169.466 | Q5: =IF(OR($O5="",$I5<Q$1),"",$J5+P5) -> 46229.466 | R5: =IF(OR($O5="",$I5<R$1),"",$J5+Q5) -> 46289.466 | S5: =IF(OR($O5="",$I5<S$1),"",$J5+R5) -> 46349.466 | T5: =IF(OR($O5="",$I5<T$1),"",$J5+S5) -> 46409.466 | U5: =IF(OR($O5="",$I5<U$1),"",$J5+T5) -> 46469.466 | V5: =IF(OR($O5="",$I5<V$1),"",$J5+U5) -> 46529.466 | W5: =IF(OR($O5="",$I5<W$1),"",$J5+V5) -> 46589.466 | ... AH5: =IF(OR($O5="",$I5<AH$1),"",$J5+AG5)
A6: Expected Screen Fail Rate | B6: 0.15 | D6: France | E6: No | F6: 0.05 | G6: 62 | H6: =IF(G6="","",ROUND(G6-(G6*$B$6),0)) -> 53 | I6: 1 | J6: 100 | K6: 45901 | L6: =IF(D6="","",K6+_xlfn.XLOOKUP(D6,'Country StartUp'!A:A,'Country StartUp'!B:B)) -> 46014.455 | M6: =IF(D6="","",$B$3-_xlfn.XLOOKUP(D6,'Country StartUp'!A:A,'Country StartUp'!B:B)) -> 45909.545 | O6: =IF(OR($L6="",$I6<O$1),"",$L6+J6) -> 46114.455 | P6: =IF(OR($O6="",$I6<P$1),"",$J6+O6) | Q6: =IF(OR($O6="",$I6<Q$1),"",$J6+P6) | R6: =IF(OR($O6="",$I6<R$1),"",$J6+Q6) | S6: =IF(OR($O6="",$I6<S$1),"",$J6+R6) | T6: =IF(OR($O6="",$I6<T$1),"",$J6+S6) | U6: =IF(OR($O6="",$I6<U$1),"",$J6+T6) | V6: =IF(OR($O6="",$I6<V$1),"",$J6+U6) | W6: =IF(OR($O6="",$I6<W$1),"",$J6+V6) | ... AH6: =IF(OR($O6="",$I6<AH$1),"",$J6+AG6)
A7: Expected Enrollment Rate (Global) | B7: 0.2 | D7: Italy | E7: No | G7: 40 | H7: =IF(G7="","",ROUND(G7-(G7*$B$6),0)) -> 34 | I7: 6 | J7: 30 | K7: 45962 | L7: =IF(D7="","",K7+_xlfn.XLOOKUP(D7,'Country StartUp'!A:A,'Country StartUp'!B:B)) -> 46107.769 | M7: =IF(D7="","",$B$3-_xlfn.XLOOKUP(D7,'Country StartUp'!A:A,'Country StartUp'!B:B)) -> 45877.231 | O7: =IF(OR($L7="",$I7<O$1),"",$L7+J7) -> 46137.769 | P7: =IF(OR($O7="",$I7<P$1),"",$J7+O7) -> 46167.769 | Q7: =IF(OR($O7="",$I7<Q$1),"",$J7+P7) -> 46197.769 | R7: =IF(OR($O7="",$I7<R$1),"",$J7+Q7) -> 46227.769 | S7: =IF(OR($O7="",$I7<S$1),"",$J7+R7) -> 46257.769 | T7: =IF(OR($O7="",$I7<T$1),"",$J7+S7) -> 46287.769 | U7: =IF(OR($O7="",$I7<U$1),"",$J7+T7) | V7: =IF(OR($O7="",$I7<V$1),"",$J7+U7) | W7: =IF(OR($O7="",$I7<W$1),"",$J7+V7) | ... AH7: =IF(OR($O7="",$I7<AH$1),"",$J7+AG7)
A8: Screening Window (Days) | B8: 30 | H8: =IF(G8="","",ROUND(G8-(G8*$B$6),0)) | L8: =IF(D8="","",K8+_xlfn.XLOOKUP(D8,'Country StartUp'!A:A,'Country StartUp'!B:B)) | M8: =IF(D8="","",$B$3-_xlfn.XLOOKUP(D8,'Country StartUp'!A:A,'Country StartUp'!B:B)) | O8: =IF(OR($L8="",$I8<O$1),"",$L8+J8) | P8: =IF(OR($O8="",$I8<P$1),"",$J8+O8) | Q8: =IF(OR($O8="",$I8<Q$1),"",$J8+P8) | R8: =IF(OR($O8="",$I8<R$1),"",$J8+Q8) | S8: =IF(OR($O8="",$I8<S$1),"",$J8+R8) | T8: =IF(OR($O8="",$I8<T$1),"",$J8+S8) | U8: =IF(OR($O8="",$I8<U$1),"",$J8+T8) | V8: =IF(OR($O8="",$I8<V$1),"",$J8+U8) | W8: =IF(OR($O8="",$I8<W$1),"",$J8+V8) | ... AH8: =IF(OR($O8="",$I8<AH$1),"",$J8+AG8)
H9: =IF(G9="","",ROUND(G9-(G9*$B$6),0)) | L9: =IF(D9="","",K9+_xlfn.XLOOKUP(D9,'Country StartUp'!A:A,'Country StartUp'!B:B)) | M9: =IF(D9="","",$B$3-_xlfn.XLOOKUP(D9,'Country StartUp'!A:A,'Country StartUp'!B:B)) | O9: =IF(OR($L9="",$I9<O$1),"",$L9+J9) | P9: =IF(OR($O9="",$I9<P$1),"",$J9+O9) | Q9: =IF(OR($O9="",$I9<Q$1),"",$J9+P9) | R9: =IF(OR($O9="",$I9<R$1),"",$J9+Q9) | S9: =IF(OR($O9="",$I9<S$1),"",$J9+R9) | T9: =IF(OR($O9="",$I9<T$1),"",$J9+S9) | U9: =IF(OR($O9="",$I9<U$1),"",$J9+T9) | V9: =IF(OR($O9="",$I9<V$1),"",$J9+U9) | W9: =IF(OR($O9="",$I9<W$1),"",$J9+V9) | ... AH9: =IF(OR($O9="",$I9<AH$1),"",$J9+AG9)
A10: Minimum Participants Needed to Be Screened | B10: =(B2*B6)+B2 -> 115 | H10: =IF(G10="","",ROUND(G10-(G10*$B$6),0)) | L10: =IF(D10="","",K10+_xlfn.XLOOKUP(D10,'Country StartUp'!A:A,'Country StartUp'!B:B)) | M10: =IF(D10="","",$B$3-_xlfn.XLOOKUP(D10,'Country StartUp'!A:A,'Country StartUp'!B:B)) | O10: =IF(OR($L10="",$I10<O$1),"",$L10+J10) | P10: =IF(OR($O10="",$I10<P$1),"",$J10+O10) | Q10: =IF(OR($O10="",$I10<Q$1),"",$J10+P10) | R10: =IF(OR($O10="",$I10<R$1),"",$J10+Q10) | S10: =IF(OR($O10="",$I10<S$1),"",$J10+R10) | T10: =IF(OR($O10="",$I10<T$1),"",$J10+S10) | U10: =IF(OR($O10="",$I10<U$1),"",$J10+T10) | V10: =IF(OR($O10="",$I10<V$1),"",$J10+U10) | W10: =IF(OR($O10="",$I10<W$1),"",$J10+V10) | ... AH10: =IF(OR($O10="",$I10<AH$1),"",$J10+AG10)
A11: Total Participants Projected | B11: =SUMIF($E:$E,"Yes",$H:$H) -> 101 | H11: =IF(G11="","",ROUND(G11-(G11*$B$6),0)) | L11: =IF(D11="","",K11+_xlfn.XLOOKUP(D11,'Country StartUp'!A:A,'Country StartUp'!B:B)) | M11: =IF(D11="","",$B$3-_xlfn.XLOOKUP(D11,'Country StartUp'!A:A,'Country StartUp'!B:B)) | O11: =IF(OR($L11="",$I11<O$1),"",$L11+J11) | P11: =IF(OR($O11="",$I11<P$1),"",$J11+O11) | Q11: =IF(OR($O11="",$I11<Q$1),"",$J11+P11) | R11: =IF(OR($O11="",$I11<R$1),"",$J11+Q11) | S11: =IF(OR($O11="",$I11<S$1),"",$J11+R11) | T11: =IF(OR($O11="",$I11<T$1),"",$J11+S11) | U11: =IF(OR($O11="",$I11<U$1),"",$J11+T11) | V11: =IF(OR($O11="",$I11<V$1),"",$J11+U11) | W11: =IF(OR($O11="",$I11<W$1),"",$J11+V11) | ... AH11: =IF(OR($O11="",$I11<AH$1),"",$J11+AG11)
H12: =IF(G12="","",ROUND(G12-(G12*$B$6),0)) | L12: =IF(D12="","",K12+_xlfn.XLOOKUP(D12,'Country StartUp'!A:A,'Country StartUp'!B:B)) | M12: =IF(D12="","",$B$3-_xlfn.XLOOKUP(D12,'Country StartUp'!A:A,'Country StartUp'!B:B)) | O12: =IF(OR($L12="",$I12<O$1),"",$L12+J12) | P12: =IF(OR($O12="",$I12<P$1),"",$J12+O12) | Q12: =IF(OR($O12="",$I12<Q$1),"",$J12+P12) | R12: =IF(OR($O12="",$I12<R$1),"",$J12+Q12) | S12: =IF(OR($O12="",$I12<S$1),"",$J12+R12) | T12: =IF(OR($O12="",$I12<T$1),"",$J12+S12) | U12: =IF(OR($O12="",$I12<U$1),"",$J12+T12) | V12: =IF(OR($O12="",$I12<V$1),"",$J12+U12) | W12: =IF(OR($O12="",$I12<W$1),"",$J12+V12) | ... AH12: =IF(OR($O12="",$I12<AH$1),"",$J12+AG12)
H13: =IF(G13="","",ROUND(G13-(G13*$B$6),0)) | L13: =IF(D13="","",K13+_xlfn.XLOOKUP(D13,'Country StartUp'!A:A,'Country StartUp'!B:B)) | M13: =IF(D13="","",$B$3-_xlfn.XLOOKUP(D13,'Country StartUp'!A:A,'Country StartUp'!B:B)) | O13: =IF(OR($L13="",$I13<O$1),"",$L13+J13) | P13: =IF(OR($O13="",$I13<P$1),"",$J13+O13) | Q13: =IF(OR($O13="",$I13<Q$1),"",$J13+P13) | R13: =IF(OR($O13="",$I13<R$1),"",$J13+Q13) | S13: =IF(OR($O13="",$I13<S$1),"",$J13+R13) | T13: =IF(OR($O13="",$I13<T$1),"",$J13+S13) | U13: =IF(OR($O13="",$I13<U$1),"",$J13+T13) | V13: =IF(OR($O13="",$I13<V$1),"",$J13+U13) | W13: =IF(OR($O13="",$I13<W$1),"",$J13+V13) | ... AH13: =IF(OR($O13="",$I13<AH$1),"",$J13+AG13)
H14: =IF(G14="","",ROUND(G14-(G14*$B$6),0)) | L14: =IF(D14="","",K14+_xlfn.XLOOKUP(D14,'Country StartUp'!A:A,'Country StartUp'!B:B)) | M14: =IF(D14="","",$B$3-_xlfn.XLOOKUP(D14,'Country StartUp'!A:A,'Country StartUp'!B:B)) | O14: =IF(OR($L14="",$I14<O$1),"",$L14+J14) | P14: =IF(OR($O14="",$I14<P$1),"",$J14+O14) | Q14: =IF(OR($O14="",$I14<Q$1),"",$J14+P14) | R14: =IF(OR($O14="",$I14<R$1),"",$J14+Q14) | S14: =IF(OR($O14="",$I14<S$1),"",$J14+R14) | T14: =IF(OR($O14="",$I14<T$1),"",$J14+S14) | U14: =IF(OR($O14="",$I14<U$1),"",$J14+T14) | V14: =IF(OR($O14="",$I14<V$1),"",$J14+U14) | W14: =IF(OR($O14="",$I14<W$1),"",$J14+V14) | ... AH14: =IF(OR($O14="",$I14<AH$1),"",$J14+AG14)
H15: =IF(G15="","",ROUND(G15-(G15*$B$6),0)) | L15: =IF(D15="","",K15+_xlfn.XLOOKUP(D15,'Country StartUp'!A:A,'Country StartUp'!B:B)) | M15: =IF(D15="","",$B$3-_xlfn.XLOOKUP(D15,'Country StartUp'!A:A,'Country StartUp'!B:B)) | O15: =IF(OR($L15="",$I15<O$1),"",$L15+J15) | P15: =IF(OR($O15="",$I15<P$1),"",$J15+O15) | Q15: =IF(OR($O15="",$I15<Q$1),"",$J15+P15) | R15: =IF(OR($O15="",$I15<R$1),"",$J15+Q15) | S15: =IF(OR($O15="",$I15<S$1),"",$J15+R15) | T15: =IF(OR($O15="",$I15<T$1),"",$J15+S15) | U15: =IF(OR($O15="",$I15<U$1),"",$J15+T15) | V15: =IF(OR($O15="",$I15<V$1),"",$J15+U15) | W15: =IF(OR($O15="",$I15<W$1),"",$J15+V15) | ... AH15: =IF(OR($O15="",$I15<AH$1),"",$J15+AG15)
H16: =IF(G16="","",ROUND(G16-(G16*$B$6),0)) | L16: =IF(D16="","",K16+_xlfn.XLOOKUP(D16,'Country StartUp'!A:A,'Country StartUp'!B:B)) | M16: =IF(D16="","",$B$3-_xlfn.XLOOKUP(D16,'Country StartUp'!A:A,'Country StartUp'!B:B)) | O16: =IF(OR($L16="",$I16<O$1),"",$L16+J16) | P16: =IF(OR($O16="",$I16<P$1),"",$J16+O16) | Q16: =IF(OR($O16="",$I16<Q$1),"",$J16+P16) | R16: =IF(OR($O16="",$I16<R$1),"",$J16+Q16) | S16: =IF(OR($O16="",$I16<S$1),"",$J16+R16) | T16: =IF(OR($O16="",$I16<T$1),"",$J16+S16) | U16: =IF(OR($O16="",$I16<U$1),"",$J16+T16) | V16: =IF(OR($O16="",$I16<V$1),"",$J16+U16) | W16: =IF(OR($O16="",$I16<W$1),"",$J16+V16) | ... AH16: =IF(OR($O16="",$I16<AH$1),"",$J16+AG16)
H17: =IF(G17="","",ROUND(G17-(G17*$B$6),0)) | L17: =IF(D17="","",K17+_xlfn.XLOOKUP(D17,'Country StartUp'!A:A,'Country StartUp'!B:B)) | M17: =IF(D17="","",$B$3-_xlfn.XLOOKUP(D17,'Country StartUp'!A:A,'Country StartUp'!B:B)) | O17: =IF(OR($L17="",$I17<O$1),"",$L17+J17) | P17: =IF(OR($O17="",$I17<P$1),"",$J17+O17) | Q17: =IF(OR($O17="",$I17<Q$1),"",$J17+P17) | R17: =IF(OR($O17="",$I17<R$1),"",$J17+Q17) | S17: =IF(OR($O17="",$I17<S$1),"",$J17+R17) | T17: =IF(OR($O17="",$I17<T$1),"",$J17+S17) | U17: =IF(OR($O17="",$I17<U$1),"",$J17+T17) | V17: =IF(OR($O17="",$I17<V$1),"",$J17+U17) | W17: =IF(OR($O17="",$I17<W$1),"",$J17+V17) | ... AH17: =IF(OR($O17="",$I17<AH$1),"",$J17+AG17)
H18: =IF(G18="","",ROUND(G18-(G18*$B$6),0)) | L18: =IF(D18="","",K18+_xlfn.XLOOKUP(D18,'Country StartUp'!A:A,'Country StartUp'!B:B)) | M18: =IF(D18="","",$B$3-_xlfn.XLOOKUP(D18,'Country StartUp'!A:A,'Country StartUp'!B:B)) | O18: =IF(OR($L18="",$I18<O$1),"",$L18+J18) | P18: =IF(OR($O18="",$I18<P$1),"",$J18+O18) | Q18: =IF(OR($O18="",$I18<Q$1),"",$J18+P18) | R18: =IF(OR($O18="",$I18<R$1),"",$J18+Q18) | S18: =IF(OR($O18="",$I18<S$1),"",$J18+R18) | T18: =IF(OR($O18="",$I18<T$1),"",$J18+S18) | U18: =IF(OR($O18="",$I18<U$1),"",$J18+T18) | V18: =IF(OR($O18="",$I18<V$1),"",$J18+U18) | W18: =IF(OR($O18="",$I18<W$1),"",$J18+V18) | ... AH18: =IF(OR($O18="",$I18<AH$1),"",$J18+AG18)
H19: =IF(G19="","",ROUND(G19-(G19*$B$6),0)) | L19: =IF(D19="","",K19+_xlfn.XLOOKUP(D19,'Country StartUp'!A:A,'Country StartUp'!B:B)) | M19: =IF(D19="","",$B$3-_xlfn.XLOOKUP(D19,'Country StartUp'!A:A,'Country StartUp'!B:B)) | O19: =IF(OR($L19="",$I19<O$1),"",$L19+J19) | P19: =IF(OR($O19="",$I19<P$1),"",$J19+O19) | Q19: =IF(OR($O19="",$I19<Q$1),"",$J19+P19) | R19: =IF(OR($O19="",$I19<R$1),"",$J19+Q19) | S19: =IF(OR($O19="",$I19<S$1),"",$J19+R19) | T19: =IF(OR($O19="",$I19<T$1),"",$J19+S19) | U19: =IF(OR($O19="",$I19<U$1),"",$J19+T19) | V19: =IF(OR($O19="",$I19<V$1),"",$J19+U19) | W19: =IF(OR($O19="",$I19<W$1),"",$J19+V19) | ... AH19: =IF(OR($O19="",$I19<AH$1),"",$J19+AG19)
H20: =IF(G20="","",ROUND(G20-(G20*$B$6),0)) | L20: =IF(D20="","",K20+_xlfn.XLOOKUP(D20,'Country StartUp'!A:A,'Country StartUp'!B:B)) | M20: =IF(D20="","",$B$3-_xlfn.XLOOKUP(D20,'Country StartUp'!A:A,'Country StartUp'!B:B)) | O20: =IF(OR($L20="",$I20<O$1),"",$L20+J20) | P20: =IF(OR($O20="",$I20<P$1),"",$J20+O20) | Q20: =IF(OR($O20="",$I20<Q$1),"",$J20+P20) | R20: =IF(OR($O20="",$I20<R$1),"",$J20+Q20) | S20: =IF(OR($O20="",$I20<S$1),"",$J20+R20) | T20: =IF(OR($O20="",$I20<T$1),"",$J20+S20) | U20: =IF(OR($O20="",$I20<U$1),"",$J20+T20) | V20: =IF(OR($O20="",$I20<V$1),"",$J20+U20) | W20: =IF(OR($O20="",$I20<W$1),"",$J20+V20) | ... AH20: =IF(OR($O20="",$I20<AH$1),"",$J20+AG20)
H21: =IF(G21="","",ROUND(G21-(G21*$B$6),0)) | L21: =IF(D21="","",K21+_xlfn.XLOOKUP(D21,'Country StartUp'!A:A,'Country StartUp'!B:B)) | M21: =IF(D21="","",$B$3-_xlfn.XLOOKUP(D21,'Country StartUp'!A:A,'Country StartUp'!B:B)) | O21: =IF(OR($L21="",$I21<O$1),"",$L21+J21) | P21: =IF(OR($O21="",$I21<P$1),"",$J21+O21) | Q21: =IF(OR($O21="",$I21<Q$1),"",$J21+P21) | R21: =IF(OR($O21="",$I21<R$1),"",$J21+Q21) | S21: =IF(OR($O21="",$I21<S$1),"",$J21+R21) | T21: =IF(OR($O21="",$I21<T$1),"",$J21+S21) | U21: =IF(OR($O21="",$I21<U$1),"",$J21+T21) | V21: =IF(OR($O21="",$I21<V$1),"",$J21+U21) | W21: =IF(OR($O21="",$I21<W$1),"",$J21+V21) | ... AH21: =IF(OR($O21="",$I21<AH$1),"",$J21+AG21)
H22: =IF(G22="","",ROUND(G22-(G22*$B$6),0)) | L22: =IF(D22="","",K22+_xlfn.XLOOKUP(D22,'Country StartUp'!A:A,'Country StartUp'!B:B)) | M22: =IF(D22="","",$B$3-_xlfn.XLOOKUP(D22,'Country StartUp'!A:A,'Country StartUp'!B:B)) | O22: =IF(OR($L22="",$I22<O$1),"",$L22+J22) | P22: =IF(OR($O22="",$I22<P$1),"",$J22+O22) | Q22: =IF(OR($O22="",$I22<Q$1),"",$J22+P22) | R22: =IF(OR($O22="",$I22<R$1),"",$J22+Q22) | S22: =IF(OR($O22="",$I22<S$1),"",$J22+R22) | T22: =IF(OR($O22="",$I22<T$1),"",$J22+S22) | U22: =IF(OR($O22="",$I22<U$1),"",$J22+T22) | V22: =IF(OR($O22="",$I22<V$1),"",$J22+U22) | W22: =IF(OR($O22="",$I22<W$1),"",$J22+V22) | ... AH22: =IF(OR($O22="",$I22<AH$1),"",$J22+AG22)
H23: =IF(G23="","",ROUND(G23-(G23*$B$6),0)) | L23: =IF(D23="","",K23+_xlfn.XLOOKUP(D23,'Country StartUp'!A:A,'Country StartUp'!B:B)) | M23: =IF(D23="","",$B$3-_xlfn.XLOOKUP(D23,'Country StartUp'!A:A,'Country StartUp'!B:B)) | O23: =IF(OR($L23="",$I23<O$1),"",$L23+J23) | P23: =IF(OR($O23="",$I23<P$1),"",$J23+O23) | Q23: =IF(OR($O23="",$I23<Q$1),"",$J23+P23) | R23: =IF(OR($O23="",$I23<R$1),"",$J23+Q23) | S23: =IF(OR($O23="",$I23<S$1),"",$J23+R23) | T23: =IF(OR($O23="",$I23<T$1),"",$J23+S23) | U23: =IF(OR($O23="",$I23<U$1),"",$J23+T23) | V23: =IF(OR($O23="",$I23<V$1),"",$J23+U23) | W23: =IF(OR($O23="",$I23<W$1),"",$J23+V23) | ... AH23: =IF(OR($O23="",$I23<AH$1),"",$J23+AG23)
L24: =IF(D24="","",K24+_xlfn.XLOOKUP(D24,'Country StartUp'!A:A,'Country StartUp'!B:B)) | M24: =IF(D24="","",$B$3-_xlfn.XLOOKUP(D24,'Country StartUp'!A:A,'Country StartUp'!B:B)) | O24: =IF(OR($L24="",$I24<O$1),"",$L24+J24) | P24: =IF(OR($O24="",$I24<P$1),"",$J24+O24) | Q24: =IF(OR($O24="",$I24<Q$1),"",$J24+P24) | R24: =IF(OR($O24="",$I24<R$1),"",$J24+Q24) | S24: =IF(OR($O24="",$I24<S$1),"",$J24+R24) | T24: =IF(OR($O24="",$I24<T$1),"",$J24+S24) | U24: =IF(OR($O24="",$I24<U$1),"",$J24+T24) | V24: =IF(OR($O24="",$I24<V$1),"",$J24+U24) | W24: =IF(OR($O24="",$I24<W$1),"",$J24+V24) | ... AH24: =IF(OR($O24="",$I24<AH$1),"",$J24+AG24)

Sheet Site Information
A1: Country | B1: Site | C1: Site Activation Date | D1: Monthly Enrollment Rate | E1: Site ER Global or Country Specific) | F1: Max Participants | G1: Current Enrollment | H1: Include? | I1: Scenario? | J1: Check Yes/No | K1: Site Amounts | O1: Global
A2: =IF(N2="","",N2) -> United States | B2: =_xlfn.CONCAT(tblSites[[#This Row],[Country]],tblSites[[#This Row],[Site Amounts]]) -> United States1 | C2: =_xlfn.IFNA(INDEX('Study Information'!$O$1:$AH$24,MATCH(tblSites[[#This Row],[Country]],'Study Information'!$D:$D,0),MATCH(tblSites[[#This Row],[Site Amounts]],'Study Information'!$O$1:$AH$1,0)),"") -> 45899 | D2: =IF(tblSites[[#This Row],[Country]]="","",IF(tblSites[[#This Row],[Site ER Global or Country Specific)]]="","Select ER",IF(tblSites[[#This Row],[Site ER Global or Country Specific)]]="Global",'Study Information'!$B$7,IF(tblSites[[#This Row],[Site ER Global or Country Specific)]]="Country Specific",_xlfn.IFNA(_xlfn.XLOOKUP(tblSites[[#This Row],[Country]],'Study Information'!$D:$D,'Study Information'!$F:$F),"Country Not Found"),"Country Not Found")))) -> 0.3 | E2: Country Specific | F2: =IFERROR(INT((_xlfn.XLOOKUP(A2,'Study Information'!D:D,'Study Information'!H:H)-SUMIFS($G:$G,$A:$A,A2,$G:$G,">0"))/(_xlfn.XLOOKUP(A2,'Study Information'!D:D,'Study Information'!I:I)))+IF(K2<=MOD(_xlfn.XLOOKUP(A2,'Study Information'!D:D,'Study Information'!H:H)-SUMIFS($G:$G,$A:$A,A2,$G:$G,">0"),_xlfn.XLOOKUP(A2,'Study Information'!D:D,'Study Information'!I:I)),1,0),"") -> 10 | H2: =IF(tblSites[[#This Row],[Country]]="","",_xlfn.XLOOKUP(tblSites[[#This Row],[Country]],'Study Information'!$D:$D,'Study Information'!$E:$E)) -> Yes | I2: =IF(A2="","",IF(H2="Yes","",_xlfn.IFNA(IF(_xlfn.XLOOKUP(tblSites[[#This Row],[Country]],'Scenario Tool'!$B:$B,'Scenario Tool'!$A:$A)=0,"",_xlfn.XLOOKUP(tblSites[[#This Row],[Country]],'Scenario Tool'!$B:$B,'Scenario Tool'!$A:$A)),"Not Specified"))) | J2: =IF(AND(tblSites[[#This Row],[Include?]]="YES",tblSites[[#This Row],[Scenario?]]="YES"),"Scenario and Include both Yes","") | K2: =IF(tblSites[[#This Row],[Country]]="","",COUNTIF($A$2:A2,A2)) -> 1 | N2: {=IF(_xlfn.LET(_xlpm.countries,'Study Information'!$D$2:$D$24,_xlpm.counts,'Study Information'!$I$2:$I$24,_xlpm.total,SUM(_xlpm.counts),_xlpm.seq,_xlfn.SEQUENCE(_xlpm.total),INDEX(_xlpm.countries,_xlfn.XMATCH(_xlpm.seq,_xlfn.SCAN(0,_xlpm.counts,_xlfn.LAMBDA(_xlpm.a,_xlpm.b,_xlpm.a+_xlpm.b)),1)))=0,"",_xlfn.LET(_xlpm.countries,'Study Information'!$D$2:$D$24,_xlpm.counts,'Study Information'!$I$2:$I$24,_xlpm.total,SUM(_xlpm.counts),_xlpm.seq,_xlfn.SEQUENCE(_xlpm.total),INDEX(_xlpm.countries,_xlfn.XMATCH(_xlpm.seq,_xlfn.SCAN(0,_xlpm.counts,_xlfn.LAMBDA(_xlpm.a,_xlpm.b,_xlpm.a+_xlpm.b)),1))))} -> United States | O2: Country Specific
A3: =IF(N3="","",N3) -> United States | B3: =_xlfn.CONCAT(tblSites[[#This Row],[Country]],tblSites[[#This Row],[Site Amounts]]) -> United States2 | C3: =_xlfn.IFNA(INDEX('Study Information'!$O$1:$AH$24,MATCH(tblSites[[#This Row],[Country]],'Study Information'!$D:$D,0),MATCH(tblSites[[#This Row],[Site Amounts]],'Study Information'!$O$1:$AH$1,0)),"") -> 45929 | D3: =IF(tblSites[[#This Row],[Country]]="","",IF(tblSites[[#This Row],[Site ER Global or Country Specific)]]="","Select ER",IF(tblSites[[#This Row],[Site ER Global or Country Specific)]]="Global",'Study Information'!$B$7,IF(tblSites[[#This Row],[Site ER Global or Country Specific)]]="Country Specific",_xlfn.IFNA(_xlfn.XLOOKUP(tblSites[[#This Row],[Country]],'Study Information'!$D:$D,'Study Information'!$F:$F),"Country Not Found"),"Country Not Found")))) -> 0.3 | E3: Country Specific | F3: =IFERROR(INT((_xlfn.XLOOKUP(A3,'Study Information'!D:D,'Study Information'!H:H)-SUMIFS($G:$G,$A:$A,A3,$G:$G,">0"))/(_xlfn.XLOOKUP(A3,'Study Information'!D:D,'Study Information'!I:I)))+IF(K3<=MOD(_xlfn.XLOOKUP(A3,'Study Information'!D:D,'Study Information'!H:H)-SUMIFS($G:$G,$A:$A,A3,$G:$G,">0"),_xlfn.XLOOKUP(A3,'Study Information'!D:D,'Study Information'!I:I)),1,0),"") -> 9 | H3: =IF(tblSites[[#This Row],[Country]]="","",_xlfn.XLOOKUP(tblSites[[#This Row],[Country]],'Study Information'!$D:$D,'Study Information'!$E:$E)) -> Yes | I3: =IF(A3="","",IF(H3="Yes","",_xlfn.IFNA(IF(_xlfn.XLOOKUP(tblSites[[#This Row],[Country]],'Scenario Tool'!$B:$B,'Scenario Tool'!$A:$A)=0,"",_xlfn.XLOOKUP(tblSites[[#This Row],[Country]],'Scenario Tool'!$B:$B,'Scenario Tool'!$A:$A)),"Not Specified"))) | J3: =IF(AND(tblSites[[#This Row],[Include?]]="YES",tblSites[[#This Row],[Scenario?]]="YES"),"Scenario and Include both Yes","") | K3: =IF(tblSites[[#This Row],[Country]]="","",COUNTIF($A$2:A3,A3)) -> 2 | N3: United States
A4: =IF(N4="","",N4) -> United States | B4: =_xlfn.CONCAT(tblSites[[#This Row],[Country]],tblSites[[#This Row],[Site Amounts]]) -> United States3 | C4: =_xlfn.IFNA(INDEX('Study Information'!$O$1:$AH$24,MATCH(tblSites[[#This Row],[Country]],'Study Information'!$D:$D,0),MATCH(tblSites[[#This Row],[Site Amounts]],'Study Information'!$O$1:$AH$1,0)),"") -> 45959 | D4: =IF(tblSites[[#This Row],[Country]]="","",IF(tblSites[[#This Row],[Site ER Global or Country Specific)]]="","Select ER",IF(tblSites[[#This Row],[Site ER Global or Country Specific)]]="Global",'Study Information'!$B$7,IF(tblSites[[#This Row],[Site ER Global or Country Specific)]]="Country Specific",_xlfn.IFNA(_xlfn.XLOOKUP(tblSites[[#This Row],[Country]],'Study Information'!$D:$D,'Study Information'!$F:$F),"Country Not Found"),"Country Not Found")))) -> 0.3 | E4: Country Specific | F4: =IFERROR(INT((_xlfn.XLOOKUP(A4,'Study Information'!D:D,'Study Information'!H:H)-SUMIFS($G:$G,$A:$A,A4,$G:$G,">0"))/(_xlfn.XLOOKUP(A4,'Study Information'!D:D,'Study Information'!I:I)))+IF(K4<=MOD(_xlfn.XLOOKUP(A4,'Study Information'!D:D,'Study Information'!H:H)-SUMIFS($G:$G,$A:$A,A4,$G:$G,">0"),_xlfn.XLOOKUP(A4,'Study Information'!D:D,'Study Information'!I:I)),1,0),"") -> 9 | H4: =IF(tblSites[[#This Row],[Country]]="","",_xlfn.XLOOKUP(tblSites[[#This Row],[Country]],'Study Information'!$D:$D,'Study Information'!$E:$E)) -> Yes | I4: =IF(A4="","",IF(H4="Yes","",_xlfn.IFNA(IF(_xlfn.XLOOKUP(tblSites[[#This Row],[Country]],'Scenario Tool'!$B:$B,'Scenario Tool'!$A:$A)=0,"",_xlfn.XLOOKUP(tblSites[[#This Row],[Country]],'Scenario Tool'!$B:$B,'Scenario Tool'!$A:$A)),"Not Specified"))) | J4: =IF(AND(tblSites[[#This Row],[Include?]]="YES",tblSites[[#This Row],[Scenario?]]="YES"),"Scenario and Include both Yes","") | K4: =IF(tblSites[[#This Row],[Country]]="","",COUNTIF($A$2:A4,A4)) -> 3 | N4: United States
A5: =IF(N5="","",N5) -> United States | B5: =_xlfn.CONCAT(tblSites[[#This Row],[Country]],tblSites[[#This Row],[Site Amounts]]) -> United States4 | C5: =_xlfn.IFNA(INDEX('Study Information'!$O$1:$AH$24,MATCH(tblSites[[#This Row],[Country]],'Study Information'!$D:$D,0),MATCH(tblSites[[#This Row],[Site Amounts]],'Study Information'!$O$1:$AH$1,0)),"") -> 45989 | D5: =IF(tblSites[[#This Row],[Country]]="","",IF(tblSites[[#This Row],[Site ER Global or Country Specific)]]="","Select ER",IF(tblSites[[#This Row],[Site ER Global or Country Specific)]]="Global",'Study Information'!$B$7,IF(tblSites[[#This Row],[Site ER Global or Country Specific)]]="Country Specific",_xlfn.IFNA(_xlfn.XLOOKUP(tblSites[[#This Row],[Country]],'Study Information'!$D:$D,'Study Information'!$F:$F),"Country Not Found"),"Country Not Found")))) -> 0.3 | E5: Country Specific | F5: =IFERROR(INT((_xlfn.XLOOKUP(A5,'Study Information'!D:D,'Study Information'!H:H)-SUMIFS($G:$G,$A:$A,A5,$G:$G,">0"))/(_xlfn.XLOOKUP(A5,'Study Information'!D:D,'Study Information'!I:I)))+IF(K5<=MOD(_xlfn.XLOOKUP(A5,'Study Information'!D:D,'Study Information'!H:H)-SUMIFS($G:$G,$A:$A,A5,$G:$G,">0"),_xlfn.XLOOKUP(A5,'Study Information'!D:D,'Study Information'!I:I)),1,0),"") -> 9 | H5: =IF(tblSites[[#This Row],[Country]]="","",_xlfn.XLOOKUP(tblSites[[#This Row],[Country]],'Study Information'!$D:$D,'Study Information'!$E:$E)) -> Yes | I5: =IF(A5="","",IF(H5="Yes","",_xlfn.IFNA(IF(_xlfn.XLOOKUP(tblSites[[#This Row],[Country]],'Scenario Tool'!$B:$B,'Scenario Tool'!$A:$A)=0,"",_xlfn.XLOOKUP(tblSites[[#This Row],[Country]],'Scenario Tool'!$B:$B,'Scenario Tool'!$A:$A)),"Not Specified"))) | J5: =IF(AND(tblSites[[#This Row],[Include?]]="YES",tblSites[[#This Row],[Scenario?]]="YES"),"Scenario and Include both Yes","") | K5: =IF(tblSites[[#This Row],[Country]]="","",COUNTIF($A$2:A5,A5)) -> 4 | N5: United States
A6: =IF(N6="","",N6) -> Germany | B6: =_xlfn.CONCAT(tblSites[[#This Row],[Country]],tblSites[[#This Row],[Site Amounts]]) -> Germany1 | C6: =_xlfn.IFNA(INDEX('Study Information'!$O$1:$AH$24,MATCH(tblSites[[#This Row],[Country]],'Study Information'!$D:$D,0),MATCH(tblSites[[#This Row],[Site Amounts]],'Study Information'!$O$1:$AH$1,0)),"") -> 46041.545 | D6: =IF(tblSites[[#This Row],[Country]]="","",IF(tblSites[[#This Row],[Site ER Global or Country Specific)]]="","Select ER",IF(tblSites[[#This Row],[Site ER Global or Country Specific)]]="Global",'Study Information'!$B$7,IF(tblSites[[#This Row],[Site ER Global or Country Specific)]]="Country Specific",_xlfn.IFNA(_xlfn.XLOOKUP(tblSites[[#This Row],[Country]],'Study Information'!$D:$D,'Study Information'!$F:$F),"Country Not Found"),"Country Not Found")))) -> 0.1 | E6: Country Specific | F6: =IFERROR(INT((_xlfn.XLOOKUP(A6,'Study Information'!D:D,'Study Information'!H:H)-SUMIFS($G:$G,$A:$A,A6,$G:$G,">0"))/(_xlfn.XLOOKUP(A6,'Study Information'!D:D,'Study Information'!I:I)))+IF(K6<=MOD(_xlfn.XLOOKUP(A6,'Study Information'!D:D,'Study Information'!H:H)-SUMIFS($G:$G,$A:$A,A6,$G:$G,">0"),_xlfn.XLOOKUP(A6,'Study Information'!D:D,'Study Information'!I:I)),1,0),"") -> 6 | H6: =IF(tblSites[[#This Row],[Country]]="","",_xlfn.XLOOKUP(tblSites[[#This Row],[Country]],'Study Information'!$D:$D,'Study Information'!$E:$E)) -> Yes | I6: =IF(A6="","",IF(H6="Yes","",_xlfn.IFNA(IF(_xlfn.XLOOKUP(tblSites[[#This Row],[Country]],'Scenario Tool'!$B:$B,'Scenario Tool'!$A:$A)=0,"",_xlfn.XLOOKUP(tblSites[[#This Row],[Country]],'Scenario Tool'!$B:$B,'Scenario Tool'!$A:$A)),"Not Specified"))) | J6: =IF(AND(tblSites[[#This Row],[Include?]]="YES",tblSites[[#This Row],[Scenario?]]="YES"),"Scenario and Include both Yes","") | K6: =IF(tblSites[[#This Row],[Country]]="","",COUNTIF($A$2:A6,A6)) -> 1 | N6: Germany
A7: =IF(N7="","",N7) -> Germany | B7: =_xlfn.CONCAT(tblSites[[#This Row],[Country]],tblSites[[#This Row],[Site Amounts]]) -> Germany2 | C7: =_xlfn.IFNA(INDEX('Study Information'!$O$1:$AH$24,MATCH(tblSites[[#This Row],[Country]],'Study Information'!$D:$D,0),MATCH(tblSites[[#This Row],[Site Amounts]],'Study Information'!$O$1:$AH$1,0)),"") -> 46086.545 | D7: =IF(tblSites[[#This Row],[Country]]="","",IF(tblSites[[#This Row],[Site ER Global or Country Specific)]]="","Select ER",IF(tblSites[[#This Row],[Site ER Global or Country Specific)]]="Global",'Study Information'!$B$7,IF(tblSites[[#This Row],[Site ER Global or Country Specific)]]="Country Specific",_xlfn.IFNA(_xlfn.XLOOKUP(tblSites[[#This Row],[Country]],'Study Information'!$D:$D,'Study Information'!$F:$F),"Country Not Found"),"Country Not Found")))) -> 0.1 | E7: Country Specific | F7: =IFERROR(INT((_xlfn.XLOOKUP(A7,'Study Information'!D:D,'Study Information'!H:H)-SUMIFS($G:$G,$A:$A,A7,$G:$G,">0"))/(_xlfn.XLOOKUP(A7,'Study Information'!D:D,'Study Information'!I:I)))+IF(K7<=MOD(_xlfn.XLOOKUP(A7,'Study Information'!D:D,'Study Information'!H:H)-SUMIFS($G:$G,$A:$A,A7,$G:$G,">0"),_xlfn.XLOOKUP(A7,'Study Information'!D:D,'Study Information'!I:I)),1,0),"") -> 6 | H7: =IF(tblSites[[#This Row],[Country]]="","",_xlfn.XLOOKUP(tblSites[[#This Row],[Country]],'Study Information'!$D:$D,'Study Information'!$E:$E)) -> Yes | I7: =IF(A7="","",IF(H7="Yes","",_xlfn.IFNA(IF(_xlfn.XLOOKUP(tblSites[[#This Row],[Country]],'Scenario Tool'!$B:$B,'Scenario Tool'!$A:$A)=0,"",_xlfn.XLOOKUP(tblSites[[#This Row],[Country]],'Scenario Tool'!$B:$B,'Scenario Tool'!$A:$A)),"Not Specified"))) | J7: =IF(AND(tblSites[[#This Row],[Include?]]="YES",tblSites[[#This Row],[Scenario?]]="YES"),"Scenario and Include both Yes","") | K7: =IF(tblSites[[#This Row],[Country]]="","",COUNTIF($A$2:A7,A7)) -> 2 | N7: Germany
A8: =IF(N8="","",N8) -> Germany | B8: =_xlfn.CONCAT(tblSites[[#This Row],[Country]],tblSites[[#This Row],[Site Amounts]]) -> Germany3 | C8: =_xlfn.IFNA(INDEX('Study Information'!$O$1:$AH$24,MATCH(tblSites[[#This Row],[Country]],'Study Information'!$D:$D,0),MATCH(tblSites[[#This Row],[Site Amounts]],'Study Information'!$O$1:$AH$1,0)),"") -> 46131.545 | D8: =IF(tblSites[[#This Row],[Country]]="","",IF(tblSites[[#This Row],[Site ER Global or Country Specific)]]="","Select ER",IF(tblSites[[#This Row],[Site ER Global or Country Specific)]]="Global",'Study Information'!$B$7,IF(tblSites[[#This Row],[Site ER Global or Country Specific)]]="Country Specific",_xlfn.IFNA(_xlfn.XLOOKUP(tblSites[[#This Row],[Country]],'Study Information'!$D:$D,'Study Information'!$F:$F),"Country Not Found"),"Country Not Found")))) -> 0.1 | E8: Country Specific | F8: =IFERROR(INT((_xlfn.XLOOKUP(A8,'Study Information'!D:D,'Study Information'!H:H)-SUMIFS($G:$G,$A:$A,A8,$G:$G,">0"))/(_xlfn.XLOOKUP(A8,'Study Information'!D:D,'Study Information'!I:I)))+IF(K8<=MOD(_xlfn.XLOOKUP(A8,'Study Information'!D:D,'Study Information'!H:H)-SUMIFS($G:$G,$A:$A,A8,$G:$G,">0"),_xlfn.XLOOKUP(A8,'Study Information'!D:D,'Study Information'!I:I)),1,0),"") -> 6 | H8: =IF(tblSites[[#This Row],[Country]]="","",_xlfn.XLOOKUP(tblSites[[#This Row],[Country]],'Study Information'!$D:$D,'Study Information'!$E:$E)) -> Yes | I8: =IF(A8="","",IF(H8="Yes","",_xlfn.IFNA(IF(_xlfn.XLOOKUP(tblSites[[#This Row],[Country]],'Scenario Tool'!$B:$B,'Scenario Tool'!$A:$A)=0,"",_xlfn.XLOOKUP(tblSites[[#This Row],[Country]],'Scenario Tool'!$B:$B,'Scenario Tool'!$A:$A)),"Not Specified"))) | J8: =IF(AND(tblSites[[#This Row],[Include?]]="YES",tblSites[[#This Row],[Scenario?]]="YES"),"Scenario and Include both Yes","") | K8: =IF(tblSites[[#This Row],[Country]]="","",COUNTIF($A$2:A8,A8)) -> 3 | N8: Germany
A9: =IF(N9="","",N9) -> Germany | B9: =_xlfn.CONCAT(tblSites[[#This Row],[Country]],tblSites[[#This Row],[Site Amounts]]) -> Germany4 | C9: =_xlfn.IFNA(INDEX('Study Information'!$O$1:$AH$24,MATCH(tblSites[[#This Row],[Country]],'Study Information'!$D:$D,0),MATCH(tblSites[[#This Row],[Site Amounts]],'Study Information'!$O$1:$AH$1,0)),"") -> 46176.545 | D9: =IF(tblSites[[#This Row],[Country]]="","",IF(tblSites[[#This Row],[Site ER Global or Country Specific)]]="","Select ER",IF(tblSites[[#This Row],[Site ER Global or Country Specific)]]="Global",'Study Information'!$B$7,IF(tblSites[[#This Row],[Site ER Global or Country Specific)]]="Country Specific",_xlfn.IFNA(_xlfn.XLOOKUP(tblSites[[#This Row],[Country]],'Study Information'!$D:$D,'Study Information'!$F:$F),"Country Not Found"),"Country Not Found")))) -> 0.1 | E9: Country Specific | F9: =IFERROR(INT((_xlfn.XLOOKUP(A9,'Study Information'!D:D,'Study Information'!H:H)-SUMIFS($G:$G,$A:$A,A9,$G:$G,">0"))/(_xlfn.XLOOKUP(A9,'Study Information'!D:D,'Study Information'!I:I)))+IF(K9<=MOD(_xlfn.XLOOKUP(A9,'Study Information'!D:D,'Study Information'!H:H)-SUMIFS($G:$G,$A:$A,A9,$G:$G,">0"),_xlfn.XLOOKUP(A9,'Study Information'!D:D,'Study Information'!I:I)),1,0),"") -> 6 | H9: =IF(tblSites[[#This Row],[Country]]="","",_xlfn.XLOOKUP(tblSites[[#This Row],[Country]],'Study Information'!$D:$D,'Study Information'!$E:$E)) -> Yes | I9: =IF(A9="","",IF(H9="Yes","",_xlfn.IFNA(IF(_xlfn.XLOOKUP(tblSites[[#This Row],[Country]],'Scenario Tool'!$B:$B,'Scenario Tool'!$A:$A)=0,"",_xlfn.XLOOKUP(tblSites[[#This Row],[Country]],'Scenario Tool'!$B:$B,'Scenario Tool'!$A:$A)),"Not Specified"))) | J9: =IF(AND(tblSites[[#This Row],[Include?]]="YES",tblSites[[#This Row],[Scenario?]]="YES"),"Scenario and Include both Yes","") | K9: =IF(tblSites[[#This Row],[Country]]="","",COUNTIF($A$2:A9,A9)) -> 4 | N9: Germany
A10: =IF(N10="","",N10) -> Germany | B10: =_xlfn.CONCAT(tblSites[[#This Row],[Country]],tblSites[[#This Row],[Site Amounts]]) -> Germany5 | C10: =_xlfn.IFNA(INDEX('Study Information'!$O$1:$AH$24,MATCH(tblSites[[#This Row],[Country]],'Study Information'!$D:$D,0),MATCH(tblSites[[#This Row],[Site Amounts]],'Study Information'!$O$1:$AH$1,0)),"") -> 46221.545 | D10: =IF(tblSites[[#This Row],[Country]]="","",IF(tblSites[[#This Row],[Site ER Global or Country Specific)]]="","Select ER",IF(tblSites[[#This Row],[Site ER Global or Country Specific)]]="Global",'Study Information'!$B$7,IF(tblSites[[#This Row],[Site ER Global or Country Specific)]]="Country Specific",_xlfn.IFNA(_xlfn.XLOOKUP(tblSites[[#This Row],[Country]],'Study Information'!$D:$D,'Study Information'!$F:$F),"Country Not Found"),"Country Not Found")))) -> 0.1 | E10: Country Specific | F10: =IFERROR(INT((_xlfn.XLOOKUP(A10,'Study Information'!D:D,'Study Information'!H:H)-SUMIFS($G:$G,$A:$A,A10,$G:$G,">0"))/(_xlfn.XLOOKUP(A10,'Study Information'!D:D,'Study Information'!I:I)))+IF(K10<=MOD(_xlfn.XLOOKUP(A10,'Study Information'!D:D,'Study Information'!H:H)-SUMIFS($G:$G,$A:$A,A10,$G:$G,">0"),_xlfn.XLOOKUP(A10,'Study Information'!D:D,'Study Information'!I:I)),1,0),"") -> 6 | H10: =IF(tblSites[[#This Row],[Country]]="","",_xlfn.XLOOKUP(tblSites[[#This Row],[Country]],'Study Information'!$D:$D,'Study Information'!$E:$E)) -> Yes | I10: =IF(A10="","",IF(H10="Yes","",_xlfn.IFNA(IF(_xlfn.XLOOKUP(tblSites[[#This Row],[Country]],'Scenario Tool'!$B:$B,'Scenario Tool'!$A:$A)=0,"",_xlfn.XLOOKUP(tblSites[[#This Row],[Country]],'Scenario Tool'!$B:$B,'Scenario Tool'!$A:$A)),"Not Specified"))) | J10: =IF(AND(tblSites[[#This Row],[Include?]]="YES",tblSites[[#This Row],[Scenario?]]="YES"),"Scenario and Include both Yes","") | K10: =IF(tblSites[[#This Row],[Country]]="","",COUNTIF($A$2:A10,A10)) -> 5 | N10: Germany
A11: =IF(N11="","",N11) -> Germany | B11: =_xlfn.CONCAT(tblSites[[#This Row],[Country]],tblSites[[#This Row],[Site Amounts]]) -> Germany6 | C11: =_xlfn.IFNA(INDEX('Study Information'!$O$1:$AH$24,MATCH(tblSites[[#This Row],[Country]],'Study Information'!$D:$D,0),MATCH(tblSites[[#This Row],[Site Amounts]],'Study Information'!$O$1:$AH$1,0)),"") -> 46266.545 | D11: =IF(tblSites[[#This Row],[Country]]="","",IF(tblSites[[#This Row],[Site ER Global or Country Specific)]]="","Select ER",IF(tblSites[[#This Row],[Site ER Global or Country Specific)]]="Global",'Study Information'!$B$7,IF(tblSites[[#This Row],[Site ER Global or Country Specific)]]="Country Specific",_xlfn.IFNA(_xlfn.XLOOKUP(tblSites[[#This Row],[Country]],'Study Information'!$D:$D,'Study Information'!$F:$F),"Country Not Found"),"Country Not Found")))) -> 0.1 | E11: Country Specific | F11: =IFERROR(INT((_xlfn.XLOOKUP(A11,'Study Information'!D:D,'Study Information'!H:H)-SUMIFS($G:$G,$A:$A,A11,$G:$G,">0"))/(_xlfn.XLOOKUP(A11,'Study Information'!D:D,'Study Information'!I:I)))+IF(K11<=MOD(_xlfn.XLOOKUP(A11,'Study Information'!D:D,'Study Information'!H:H)-SUMIFS($G:$G,$A:$A,A11,$G:$G,">0"),_xlfn.XLOOKUP(A11,'Study Information'!D:D,'Study Information'!I:I)),1,0),"") -> 6 | H11: =IF(tblSites[[#This Row],[Country]]="","",_xlfn.XLOOKUP(tblSites[[#This Row],[Country]],'Study Information'!$D:$D,'Study Information'!$E:$E)) -> Yes | I11: =IF(A11="","",IF(H11="Yes","",_xlfn.IFNA(IF(_xlfn.XLOOKUP(tblSites[[#This Row],[Country]],'Scenario Tool'!$B:$B,'Scenario Tool'!$A:$A)=0,"",_xlfn.XLOOKUP(tblSites[[#This Row],[Country]],'Scenario Tool'!$B:$B,'Scenario Tool'!$A:$A)),"Not Specified"))) | J11: =IF(AND(tblSites[[#This Row],[Include?]]="YES",tblSites[[#This Row],[Scenario?]]="YES"),"Scenario and Include both Yes","") | K11: =IF(tblSites[[#This Row],[Country]]="","",COUNTIF($A$2:A11,A11)) -> 6 | N11: Germany
A12: =IF(N12="","",N12) -> Germany | B12: =_xlfn.CONCAT(tblSites[[#This Row],[Country]],tblSites[[#This Row],[Site Amounts]]) -> Germany7 | C12: =_xlfn.IFNA(INDEX('Study Information'!$O$1:$AH$24,MATCH(tblSites[[#This Row],[Country]],'Study Information'!$D:$D,0),MATCH(tblSites[[#This Row],[Site Amounts]],'Study Information'!$O$1:$AH$1,0)),"") -> 46311.545 | D12: =IF(tblSites[[#This Row],[Country]]="","",IF(tblSites[[#This Row],[Site ER Global or Country Specific)]]="","Select ER",IF(tblSites[[#This Row],[Site ER Global or Country Specific)]]="Global",'Study Information'!$B$7,IF(tblSites[[#This Row],[Site ER Global or Country Specific)]]="Country Specific",_xlfn.IFNA(_xlfn.XLOOKUP(tblSites[[#This Row],[Country]],'Study Information'!$D:$D,'Study Information'!$F:$F),"Country Not Found"),"Country Not Found")))) -> 0.1 | E12: Country Specific | F12: =IFERROR(INT((_xlfn.XLOOKUP(A12,'Study Information'!D:D,'Study Information'!H:H)-SUMIFS($G:$G,$A:$A,A12,$G:$G,">0"))/(_xlfn.XLOOKUP(A12,'Study Information'!D:D,'Study Information'!I:I)))+IF(K12<=MOD(_xlfn.XLOOKUP(A12,'Study Information'!D:D,'Study Information'!H:H)-SUMIFS($G:$G,$A:$A,A12,$G:$G,">0"),_xlfn.XLOOKUP(A12,'Study Information'!D:D,'Study Information'!I:I)),1,0),"") -> 6 | H12: =IF(tblSites[[#This Row],[Country]]="","",_xlfn.XLOOKUP(tblSites[[#This Row],[Country]],'Study Information'!$D:$D,'Study Information'!$E:$E)) -> Yes | I12: =IF(A12="","",IF(H12="Yes","",_xlfn.IFNA(IF(_xlfn.XLOOKUP(tblSites[[#This Row],[Country]],'Scenario Tool'!$B:$B,'Scenario Tool'!$A:$A)=0,"",_xlfn.XLOOKUP(tblSites[[#This Row],[Country]],'Scenario Tool'!$B:$B,'Scenario Tool'!$A:$A)),"Not Specified"))) | J12: =IF(AND(tblSites[[#This Row],[Include?]]="YES",tblSites[[#This Row],[Scenario?]]="YES"),"Scenario and Include both Yes","") | K12: =IF(tblSites[[#This Row],[Country]]="","",COUNTIF($A$2:A12,A12)) -> 7 | N12: Germany
A13: =IF(N13="","",N13) -> Germany | B13: =_xlfn.CONCAT(tblSites[[#This Row],[Country]],tblSites[[#This Row],[Site Amounts]]) -> Germany8 | C13: =_xlfn.IFNA(INDEX('Study Information'!$O$1:$AH$24,MATCH(tblSites[[#This Row],[Country]],'Study Information'!$D:$D,0),MATCH(tblSites[[#This Row],[Site Amounts]],'Study Information'!$O$1:$AH$1,0)),"") -> 46356.545 | D13: =IF(tblSites[[#This Row],[Country]]="","",IF(tblSites[[#This Row],[Site ER Global or Country Specific)]]="","Select ER",IF(tblSites[[#This Row],[Site ER Global or Country Specific)]]="Global",'Study Information'!$B$7,IF(tblSites[[#This Row],[Site ER Global or Country Specific)]]="Country Specific",_xlfn.IFNA(_xlfn.XLOOKUP(tblSites[[#This Row],[Country]],'Study Information'!$D:$D,'Study Information'!$F:$F),"Country Not Found"),"Country Not Found")))) -> 0.1 | E13: Country Specific | F13: =IFERROR(INT((_xlfn.XLOOKUP(A13,'Study Information'!D:D,'Study Information'!H:H)-SUMIFS($G:$G,$A:$A,A13,$G:$G,">0"))/(_xlfn.XLOOKUP(A13,'Study Information'!D:D,'Study Information'!I:I)))+IF(K13<=MOD(_xlfn.XLOOKUP(A13,'Study Information'!D:D,'Study Information'!H:H)-SUMIFS($G:$G,$A:$A,A13,$G:$G,">0"),_xlfn.XLOOKUP(A13,'Study Information'!D:D,'Study Information'!I:I)),1,0),"") -> 5 | H13: =IF(tblSites[[#This Row],[Country]]="","",_xlfn.XLOOKUP(tblSites[[#This Row],[Country]],'Study Information'!$D:$D,'Study Information'!$E:$E)) -> Yes | I13: =IF(A13="","",IF(H13="Yes","",_xlfn.IFNA(IF(_xlfn.XLOOKUP(tblSites[[#This Row],[Country]],'Scenario Tool'!$B:$B,'Scenario Tool'!$A:$A)=0,"",_xlfn.XLOOKUP(tblSites[[#This Row],[Country]],'Scenario Tool'!$B:$B,'Scenario Tool'!$A:$A)),"Not Specified"))) | J13: =IF(AND(tblSites[[#This Row],[Include?]]="YES",tblSites[[#This Row],[Scenario?]]="YES"),"Scenario and Include both Yes","") | K13: =IF(tblSites[[#This Row],[Country]]="","",COUNTIF($A$2:A13,A13)) -> 8 | N13: Germany
A14: =IF(N14="","",N14) -> Canada | B14: =_xlfn.CONCAT(tblSites[[#This Row],[Country]],tblSites[[#This Row],[Site Amounts]]) -> Canada1 | C14: =_xlfn.IFNA(INDEX('Study Information'!$O$1:$AH$24,MATCH(tblSites[[#This Row],[Country]],'Study Information'!$D:$D,0),MATCH(tblSites[[#This Row],[Site Amounts]],'Study Information'!$O$1:$AH$1,0)),"") -> 46005.667 | D14: =IF(tblSites[[#This Row],[Country]]="","",IF(tblSites[[#This Row],[Site ER Global or Country Specific)]]="","Select ER",IF(tblSites[[#This Row],[Site ER Global or Country Specific)]]="Global",'Study Information'!$B$7,IF(tblSites[[#This Row],[Site ER Global or Country Specific)]]="Country Specific",_xlfn.IFNA(_xlfn.XLOOKUP(tblSites[[#This Row],[Country]],'Study Information'!$D:$D,'Study Information'!$F:$F),"Country Not Found"),"Country Not Found")))) -> 0.15 | E14: Country Specific | F14: =IFERROR(INT((_xlfn.XLOOKUP(A14,'Study Information'!D:D,'Study Information'!H:H)-SUMIFS($G:$G,$A:$A,A14,$G:$G,">0"))/(_xlfn.XLOOKUP(A14,'Study Information'!D:D,'Study Information'!I:I)))+IF(K14<=MOD(_xlfn.XLOOKUP(A14,'Study Information'!D:D,'Study Information'!H:H)-SUMIFS($G:$G,$A:$A,A14,$G:$G,">0"),_xlfn.XLOOKUP(A14,'Study Information'!D:D,'Study Information'!I:I)),1,0),"") -> 9 | H14: =IF(tblSites[[#This Row],[Country]]="","",_xlfn.XLOOKUP(tblSites[[#This Row],[Country]],'Study Information'!$D:$D,'Study Information'!$E:$E)) -> Yes | I14: =IF(A14="","",IF(H14="Yes","",_xlfn.IFNA(IF(_xlfn.XLOOKUP(tblSites[[#This Row],[Country]],'Scenario Tool'!$B:$B,'Scenario Tool'!$A:$A)=0,"",_xlfn.XLOOKUP(tblSites[[#This Row],[Country]],'Scenario Tool'!$B:$B,'Scenario Tool'!$A:$A)),"Not Specified"))) | J14: =IF(AND(tblSites[[#This Row],[Include?]]="YES",tblSites[[#This Row],[Scenario?]]="YES"),"Scenario and Include both Yes","") | K14: =IF(tblSites[[#This Row],[Country]]="","",COUNTIF($A$2:A14,A14)) -> 1 | N14: Canada
... A32: =IF(N32="","",N32) -> France | B32: =_xlfn.CONCAT(tblSites[[#This Row],[Country]],tblSites[[#This Row],[Site Amounts]]) -> France1 | C32: =_xlfn.IFNA(INDEX('Study Information'!$O$1:$AH$24,MATCH(tblSites[[#This Row],[Country]],'Study Information'!$D:$D,0),MATCH(tblSites[[#This Row],[Site Amounts]],'Study Information'!$O$1:$AH$1,0)),"") -> 46114.455 | D32: =IF(tblSites[[#This Row],[Country]]="","",IF(tblSites[[#This Row],[Site ER Global or Country Specific)]]="","Select ER",IF(tblSites[[#This Row],[Site ER Global or Country Specific)]]="Global",'Study Information'!$B$7,IF(tblSites[[#This Row],[Site ER Global or Country Specific)]]="Country Specific",_xlfn.IFNA(_xlfn.XLOOKUP(tblSites[[#This Row],[Country]],'Study Information'!$D:$D,'Study Information'!$F:$F),"Country Not Found"),"Country Not Found")))) -> 0.05 | E32: Country Specific | F32: =IFERROR(INT((_xlfn.XLOOKUP(A32,'Study Information'!D:D,'Study Information'!H:H)-SUMIFS($G:$G,$A:$A,A32,$G:$G,">0"))/(_xlfn.XLOOKUP(A32,'Study Information'!D:D,'Study Information'!I:I)))+IF(K32<=MOD(_xlfn.XLOOKUP(A32,'Study Information'!D:D,'Study Information'!H:H)-SUMIFS($G:$G,$A:$A,A32,$G:$G,">0"),_xlfn.XLOOKUP(A32,'Study Information'!D:D,'Study Information'!I:I)),1,0),"") -> 53 | H32: =IF(tblSites[[#This Row],[Country]]="","",_xlfn.XLOOKUP(tblSites[[#This Row],[Country]],'Study Information'!$D:$D,'Study Information'!$E:$E)) -> No | I32: =IF(A32="","",IF(H32="Yes","",_xlfn.IFNA(IF(_xlfn.XLOOKUP(tblSites[[#This Row],[Country]],'Scenario Tool'!$B:$B,'Scenario Tool'!$A:$A)=0,"",_xlfn.XLOOKUP(tblSites[[#This Row],[Country]],'Scenario Tool'!$B:$B,'Scenario Tool'!$A:$A)),"Not Specified"))) -> TRUE | J32: =IF(AND(tblSites[[#This Row],[Include?]]="YES",tblSites[[#This Row],[Scenario?]]="YES"),"Scenario and Include both Yes","") | K32: =IF(tblSites[[#This Row],[Country]]="","",COUNTIF($A$2:A32,A32)) -> 1 | N32: France
A33: =IF(N33="","",N33) -> Italy | B33: =_xlfn.CONCAT(tblSites[[#This Row],[Country]],tblSites[[#This Row],[Site Amounts]]) -> Italy1 | C33: =_xlfn.IFNA(INDEX('Study Information'!$O$1:$AH$24,MATCH(tblSites[[#This Row],[Country]],'Study Information'!$D:$D,0),MATCH(tblSites[[#This Row],[Site Amounts]],'Study Information'!$O$1:$AH$1,0)),"") -> 46137.769 | D33: =IF(tblSites[[#This Row],[Country]]="","",IF(tblSites[[#This Row],[Site ER Global or Country Specific)]]="","Select ER",IF(tblSites[[#This Row],[Site ER Global or Country Specific)]]="Global",'Study Information'!$B$7,IF(tblSites[[#This Row],[Site ER Global or Country Specific)]]="Country Specific",_xlfn.IFNA(_xlfn.XLOOKUP(tblSites[[#This Row],[Country]],'Study Information'!$D:$D,'Study Information'!$F:$F),"Country Not Found"),"Country Not Found")))) -> 0 | E33: Country Specific | F33: =IFERROR(INT((_xlfn.XLOOKUP(A33,'Study Information'!D:D,'Study Information'!H:H)-SUMIFS($G:$G,$A:$A,A33,$G:$G,">0"))/(_xlfn.XLOOKUP(A33,'Study Information'!D:D,'Study Information'!I:I)))+IF(K33<=MOD(_xlfn.XLOOKUP(A33,'Study Information'!D:D,'Study Information'!H:H)-SUMIFS($G:$G,$A:$A,A33,$G:$G,">0"),_xlfn.XLOOKUP(A33,'Study Information'!D:D,'Study Information'!I:I)),1,0),"") -> 6 | H33: =IF(tblSites[[#This Row],[Country]]="","",_xlfn.XLOOKUP(tblSites[[#This Row],[Country]],'Study Information'!$D:$D,'Study Information'!$E:$E)) -> No | I33: =IF(A33="","",IF(H33="Yes","",_xlfn.IFNA(IF(_xlfn.XLOOKUP(tblSites[[#This Row],[Country]],'Scenario Tool'!$B:$B,'Scenario Tool'!$A:$A)=0,"A",_xlfn.XLOOKUP(tblSites[[#This Row],[Country]],'Scenario Tool'!$B:$B,'Scenario Tool'!$A:$A)),"Not Specified"))) -> TRUE | J33: =IF(AND(tblSites[[#This Row],[Include?]]="YES",tblSites[[#This Row],[Scenario?]]="YES"),"Scenario and Include both Yes","") | K33: =IF(tblSites[[#This Row],[Country]]="","",COUNTIF($A$2:A33,A33)) -> 1 | N33: Italy
A34: =IF(N34="","",N34) -> Italy | B34: =_xlfn.CONCAT(tblSites[[#This Row],[Country]],tblSites[[#This Row],[Site Amounts]]) -> Italy2 | C34: =_xlfn.IFNA(INDEX('Study Information'!$O$1:$AH$24,MATCH(tblSites[[#This Row],[Country]],'Study Information'!$D:$D,0),MATCH(tblSites[[#This Row],[Site Amounts]],'Study Information'!$O$1:$AH$1,0)),"") -> 46167.769 | D34: =IF(tblSites[[#This Row],[Country]]="","",IF(tblSites[[#This Row],[Site ER Global or Country Specific)]]="","Select ER",IF(tblSites[[#This Row],[Site ER Global or Country Specific)]]="Global",'Study Information'!$B$7,IF(tblSites[[#This Row],[Site ER Global or Country Specific)]]="Country Specific",_xlfn.IFNA(_xlfn.XLOOKUP(tblSites[[#This Row],[Country]],'Study Information'!$D:$D,'Study Information'!$F:$F),"Country Not Found"),"Country Not Found")))) -> 0.2 | E34: Global | F34: =IFERROR(INT((_xlfn.XLOOKUP(A34,'Study Information'!D:D,'Study Information'!H:H)-SUMIFS($G:$G,$A:$A,A34,$G:$G,">0"))/(_xlfn.XLOOKUP(A34,'Study Information'!D:D,'Study Information'!I:I)))+IF(K34<=MOD(_xlfn.XLOOKUP(A34,'Study Information'!D:D,'Study Information'!H:H)-SUMIFS($G:$G,$A:$A,A34,$G:$G,">0"),_xlfn.XLOOKUP(A34,'Study Information'!D:D,'Study Information'!I:I)),1,0),"") -> 6 | H34: =IF(tblSites[[#This Row],[Country]]="","",_xlfn.XLOOKUP(tblSites[[#This Row],[Country]],'Study Information'!$D:$D,'Study Information'!$E:$E)) -> No | I34: =IF(A34="","",IF(H34="Yes","",_xlfn.IFNA(IF(_xlfn.XLOOKUP(tblSites[[#This Row],[Country]],'Scenario Tool'!$B:$B,'Scenario Tool'!$A:$A)=0,"",_xlfn.XLOOKUP(tblSites[[#This Row],[Country]],'Scenario Tool'!$B:$B,'Scenario Tool'!$A:$A)),"Not Specified"))) -> TRUE | J34: =IF(AND(tblSites[[#This Row],[Include?]]="YES",tblSites[[#This Row],[Scenario?]]="YES"),"Scenario and Include both Yes","") | K34: =IF(tblSites[[#This Row],[Country]]="","",COUNTIF($A$2:A34,A34)) -> 2 | N34: Italy
A35: =IF(N35="","",N35) -> Italy | B35: =_xlfn.CONCAT(tblSites[[#This Row],[Country]],tblSites[[#This Row],[Site Amounts]]) -> Italy3 | C35: =_xlfn.IFNA(INDEX('Study Information'!$O$1:$AH$24,MATCH(tblSites[[#This Row],[Country]],'Study Information'!$D:$D,0),MATCH(tblSites[[#This Row],[Site Amounts]],'Study Information'!$O$1:$AH$1,0)),"") -> 46197.769 | D35: =IF(tblSites[[#This Row],[Country]]="","",IF(tblSites[[#This Row],[Site ER Global or Country Specific)]]="","Select ER",IF(tblSites[[#This Row],[Site ER Global or Country Specific)]]="Global",'Study Information'!$B$7,IF(tblSites[[#This Row],[Site ER Global or Country Specific)]]="Country Specific",_xlfn.IFNA(_xlfn.XLOOKUP(tblSites[[#This Row],[Country]],'Study Information'!$D:$D,'Study Information'!$F:$F),"Country Not Found"),"Country Not Found")))) -> 0.2 | E35: Global | F35: =IFERROR(INT((_xlfn.XLOOKUP(A35,'Study Information'!D:D,'Study Information'!H:H)-SUMIFS($G:$G,$A:$A,A35,$G:$G,">0"))/(_xlfn.XLOOKUP(A35,'Study Information'!D:D,'Study Information'!I:I)))+IF(K35<=MOD(_xlfn.XLOOKUP(A35,'Study Information'!D:D,'Study Information'!H:H)-SUMIFS($G:$G,$A:$A,A35,$G:$G,">0"),_xlfn.XLOOKUP(A35,'Study Information'!D:D,'Study Information'!I:I)),1,0),"") -> 6 | H35: =IF(tblSites[[#This Row],[Country]]="","",_xlfn.XLOOKUP(tblSites[[#This Row],[Country]],'Study Information'!$D:$D,'Study Information'!$E:$E)) -> No | I35: =IF(A35="","",IF(H35="Yes","",_xlfn.IFNA(IF(_xlfn.XLOOKUP(tblSites[[#This Row],[Country]],'Scenario Tool'!$B:$B,'Scenario Tool'!$A:$A)=0,"",_xlfn.XLOOKUP(tblSites[[#This Row],[Country]],'Scenario Tool'!$B:$B,'Scenario Tool'!$A:$A)),"Not Specified"))) -> TRUE | J35: =IF(AND(tblSites[[#This Row],[Include?]]="YES",tblSites[[#This Row],[Scenario?]]="YES"),"Scenario and Include both Yes","") | K35: =IF(tblSites[[#This Row],[Country]]="","",COUNTIF($A$2:A35,A35)) -> 3 | N35: Italy
A36: =IF(N36="","",N36) -> Italy | B36: =_xlfn.CONCAT(tblSites[[#This Row],[Country]],tblSites[[#This Row],[Site Amounts]]) -> Italy4 | C36: =_xlfn.IFNA(INDEX('Study Information'!$O$1:$AH$24,MATCH(tblSites[[#This Row],[Country]],'Study Information'!$D:$D,0),MATCH(tblSites[[#This Row],[Site Amounts]],'Study Information'!$O$1:$AH$1,0)),"") -> 46227.769 | D36: =IF(tblSites[[#This Row],[Country]]="","",IF(tblSites[[#This Row],[Site ER Global or Country Specific)]]="","Select ER",IF(tblSites[[#This Row],[Site ER Global or Country Specific)]]="Global",'Study Information'!$B$7,IF(tblSites[[#This Row],[Site ER Global or Country Specific)]]="Country Specific",_xlfn.IFNA(_xlfn.XLOOKUP(tblSites[[#This Row],[Country]],'Study Information'!$D:$D,'Study Information'!$F:$F),"Country Not Found"),"Country Not Found")))) -> 0.2 | E36: Global | F36: =IFERROR(INT((_xlfn.XLOOKUP(A36,'Study Information'!D:D,'Study Information'!H:H)-SUMIFS($G:$G,$A:$A,A36,$G:$G,">0"))/(_xlfn.XLOOKUP(A36,'Study Information'!D:D,'Study Information'!I:I)))+IF(K36<=MOD(_xlfn.XLOOKUP(A36,'Study Information'!D:D,'Study Information'!H:H)-SUMIFS($G:$G,$A:$A,A36,$G:$G,">0"),_xlfn.XLOOKUP(A36,'Study Information'!D:D,'Study Information'!I:I)),1,0),"") -> 6 | H36: =IF(tblSites[[#This Row],[Country]]="","",_xlfn.XLOOKUP(tblSites[[#This Row],[Country]],'Study Information'!$D:$D,'Study Information'!$E:$E)) -> No | I36: =IF(A36="","",IF(H36="Yes","",_xlfn.IFNA(IF(_xlfn.XLOOKUP(tblSites[[#This Row],[Country]],'Scenario Tool'!$B:$B,'Scenario Tool'!$A:$A)=0,"",_xlfn.XLOOKUP(tblSites[[#This Row],[Country]],'Scenario Tool'!$B:$B,'Scenario Tool'!$A:$A)),"Not Specified"))) -> TRUE | J36: =IF(AND(tblSites[[#This Row],[Include?]]="YES",tblSites[[#This Row],[Scenario?]]="YES"),"Scenario and Include both Yes","") | K36: =IF(tblSites[[#This Row],[Country]]="","",COUNTIF($A$2:A36,A36)) -> 4 | N36: Italy
A37: =IF(N37="","",N37) -> Italy | B37: =_xlfn.CONCAT(tblSites[[#This Row],[Country]],tblSites[[#This Row],[Site Amounts]]) -> Italy5 | C37: =_xlfn.IFNA(INDEX('Study Information'!$O$1:$AH$24,MATCH(tblSites[[#This Row],[Country]],'Study Information'!$D:$D,0),MATCH(tblSites[[#This Row],[Site Amounts]],'Study Information'!$O$1:$AH$1,0)),"") -> 46257.769 | D37: =IF(tblSites[[#This Row],[Country]]="","",IF(tblSites[[#This Row],[Site ER Global or Country Specific)]]="","Select ER",IF(tblSites[[#This Row],[Site ER Global or Country Specific)]]="Global",'Study Information'!$B$7,IF(tblSites[[#This Row],[Site ER Global or Country Specific)]]="Country Specific",_xlfn.IFNA(_xlfn.XLOOKUP(tblSites[[#This Row],[Country]],'Study Information'!$D:$D,'Study Information'!$F:$F),"Country Not Found"),"Country Not Found")))) -> 0.2 | E37: Global | F37: =IFERROR(INT((_xlfn.XLOOKUP(A37,'Study Information'!D:D,'Study Information'!H:H)-SUMIFS($G:$G,$A:$A,A37,$G:$G,">0"))/(_xlfn.XLOOKUP(A37,'Study Information'!D:D,'Study Information'!I:I)))+IF(K37<=MOD(_xlfn.XLOOKUP(A37,'Study Information'!D:D,'Study Information'!H:H)-SUMIFS($G:$G,$A:$A,A37,$G:$G,">0"),_xlfn.XLOOKUP(A37,'Study Information'!D:D,'Study Information'!I:I)),1,0),"") -> 5 | H37: =IF(tblSites[[#This Row],[Country]]="","",_xlfn.XLOOKUP(tblSites[[#This Row],[Country]],'Study Information'!$D:$D,'Study Information'!$E:$E)) -> No | I37: =IF(A37="","",IF(H37="Yes","",_xlfn.IFNA(IF(_xlfn.XLOOKUP(tblSites[[#This Row],[Country]],'Scenario Tool'!$B:$B,'Scenario Tool'!$A:$A)=0,"",_xlfn.XLOOKUP(tblSites[[#This Row],[Country]],'Scenario Tool'!$B:$B,'Scenario Tool'!$A:$A)),"Not Specified"))) -> TRUE | J37: =IF(AND(tblSites[[#This Row],[Include?]]="YES",tblSites[[#This Row],[Scenario?]]="YES"),"Scenario and Include both Yes","") | K37: =IF(tblSites[[#This Row],[Country]]="","",COUNTIF($A$2:A37,A37)) -> 5 | N37: Italy
A38: =IF(N38="","",N38) -> Italy | B38: =_xlfn.CONCAT(tblSites[[#This Row],[Country]],tblSites[[#This Row],[Site Amounts]]) -> Italy6 | C38: =_xlfn.IFNA(INDEX('Study Information'!$O$1:$AH$24,MATCH(tblSites[[#This Row],[Country]],'Study Information'!$D:$D,0),MATCH(tblSites[[#This Row],[Site Amounts]],'Study Information'!$O$1:$AH$1,0)),"") -> 46287.769 | D38: =IF(tblSites[[#This Row],[Country]]="","",IF(tblSites[[#This Row],[Site ER Global or Country Specific)]]="","Select ER",IF(tblSites[[#This Row],[Site ER Global or Country Specific)]]="Global",'Study Information'!$B$7,IF(tblSites[[#This Row],[Site ER Global or Country Specific)]]="Country Specific",_xlfn.IFNA(_xlfn.XLOOKUP(tblSites[[#This Row],[Country]],'Study Information'!$D:$D,'Study Information'!$F:$F),"Country Not Found"),"Country Not Found")))) -> 0.2 | E38: Global | F38: =IFERROR(INT((_xlfn.XLOOKUP(A38,'Study Information'!D:D,'Study Information'!H:H)-SUMIFS($G:$G,$A:$A,A38,$G:$G,">0"))/(_xlfn.XLOOKUP(A38,'Study Information'!D:D,'Study Information'!I:I)))+IF(K38<=MOD(_xlfn.XLOOKUP(A38,'Study Information'!D:D,'Study Information'!H:H)-SUMIFS($G:$G,$A:$A,A38,$G:$G,">0"),_xlfn.XLOOKUP(A38,'Study Information'!D:D,'Study Information'!I:I)),1,0),"") -> 5 | H38: =IF(tblSites[[#This Row],[Country]]="","",_xlfn.XLOOKUP(tblSites[[#This Row],[Country]],'Study Information'!$D:$D,'Study Information'!$E:$E)) -> No | I38: =IF(A38="","",IF(H38="Yes","",_xlfn.IFNA(IF(_xlfn.XLOOKUP(tblSites[[#This Row],[Country]],'Scenario Tool'!$B:$B,'Scenario Tool'!$A:$A)=0,"",_xlfn.XLOOKUP(tblSites[[#This Row],[Country]],'Scenario Tool'!$B:$B,'Scenario Tool'!$A:$A)),"Not Specified"))) -> TRUE | J38: =IF(AND(tblSites[[#This Row],[Include?]]="YES",tblSites[[#This Row],[Scenario?]]="YES"),"Scenario and Include both Yes","") | K38: =IF(tblSites[[#This Row],[Country]]="","",COUNTIF($A$2:A38,A38)) -> 6 | N38: Italy
A39: =IF(N39="","",N39) | B39: =_xlfn.CONCAT(tblSites[[#This Row],[Country]],tblSites[[#This Row],[Site Amounts]]) | C39: =_xlfn.IFNA(INDEX('Study Information'!$O$1:$AH$24,MATCH(tblSites[[#This Row],[Country]],'Study Information'!$D:$D,0),MATCH(tblSites[[#This Row],[Site Amounts]],'Study Information'!$O$1:$AH$1,0)),"") | D39: =IF(tblSites[[#This Row],[Country]]="","",IF(tblSites[[#This Row],[Site ER Global or Country Specific)]]="","Select ER",IF(tblSites[[#This Row],[Site ER Global or Country Specific)]]="Global",'Study Information'!$B$7,IF(tblSites[[#This Row],[Site ER Global or Country Specific)]]="Country Specific",_xlfn.IFNA(_xlfn.XLOOKUP(tblSites[[#This Row],[Country]],'Study Information'!$D:$D,'Study Information'!$F:$F),"Country Not Found"),"Country Not Found")))) | F39: =IFERROR(INT((_xlfn.XLOOKUP(A39,'Study Information'!D:D,'Study Information'!H:H)-SUMIFS($G:$G,$A:$A,A39,$G:$G,">0"))/(_xlfn.XLOOKUP(A39,'Study Information'!D:D,'Study Information'!I:I)))+IF(K39<=MOD(_xlfn.XLOOKUP(A39,'Study Information'!D:D,'Study Information'!H:H)-SUMIFS($G:$G,$A:$A,A39,$G:$G,">0"),_xlfn.XLOOKUP(A39,'Study Information'!D:D,'Study Information'!I:I)),1,0),"") | H39: =IF(tblSites[[#This Row],[Country]]="","",_xlfn.XLOOKUP(tblSites[[#This Row],[Country]],'Study Information'!$D:$D,'Study Information'!$E:$E)) | I39: =IF(A39="","",IF(H39="Yes","",_xlfn.IFNA(IF(_xlfn.XLOOKUP(tblSites[[#This Row],[Country]],'Scenario Tool'!$B:$B,'Scenario Tool'!$A:$A)=0,"",_xlfn.XLOOKUP(tblSites[[#This Row],[Country]],'Scenario Tool'!$B:$B,'Scenario Tool'!$A:$A)),"Not Specified"))) | J39: =IF(AND(tblSites[[#This Row],[Include?]]="YES",tblSites[[#This Row],[Scenario?]]="YES"),"Scenario and Include both Yes","") | K39: =IF(tblSites[[#This Row],[Country]]="","",COUNTIF($A$2:A39,A39))
A40: =IF(N40="","",N40) | B40: =_xlfn.CONCAT(tblSites[[#This Row],[Country]],tblSites[[#This Row],[Site Amounts]]) | C40: =_xlfn.IFNA(INDEX('Study Information'!$O$1:$AH$24,MATCH(tblSites[[#This Row],[Country]],'Study Information'!$D:$D,0),MATCH(tblSites[[#This Row],[Site Amounts]],'Study Information'!$O$1:$AH$1,0)),"") | D40: =IF(tblSites[[#This Row],[Country]]="","",IF(tblSites[[#This Row],[Site ER Global or Country Specific)]]="","Select ER",IF(tblSites[[#This Row],[Site ER Global or Country Specific)]]="Global",'Study Information'!$B$7,IF(tblSites[[#This Row],[Site ER Global or Country Specific)]]="Country Specific",_xlfn.IFNA(_xlfn.XLOOKUP(tblSites[[#This Row],[Country]],'Study Information'!$D:$D,'Study Information'!$F:$F),"Country Not Found"),"Country Not Found")))) | F40: =IFERROR(INT((_xlfn.XLOOKUP(A40,'Study Information'!D:D,'Study Information'!H:H)-SUMIFS($G:$G,$A:$A,A40,$G:$G,">0"))/(_xlfn.XLOOKUP(A40,'Study Information'!D:D,'Study Information'!I:I)))+IF(K40<=MOD(_xlfn.XLOOKUP(A40,'Study Information'!D:D,'Study Information'!H:H)-SUMIFS($G:$G,$A:$A,A40,$G:$G,">0"),_xlfn.XLOOKUP(A40,'Study Information'!D:D,'Study Information'!I:I)),1,0),"") | H40: =IF(tblSites[[#This Row],[Country]]="","",_xlfn.XLOOKUP(tblSites[[#This Row],[Country]],'Study Information'!$D:$D,'Study Information'!$E:$E)) | I40: =IF(A40="","",IF(H40="Yes","",_xlfn.IFNA(IF(_xlfn.XLOOKUP(tblSites[[#This Row],[Country]],'Scenario Tool'!$B:$B,'Scenario Tool'!$A:$A)=0,"",_xlfn.XLOOKUP(tblSites[[#This Row],[Country]],'Scenario Tool'!$B:$B,'Scenario Tool'!$A:$A)),"Not Specified"))) | J40: =IF(AND(tblSites[[#This Row],[Include?]]="YES",tblSites[[#This Row],[Scenario?]]="YES"),"Scenario and Include both Yes","") | K40: =IF(tblSites[[#This Row],[Country]]="","",COUNTIF($A$2:A40,A40))
